<?xml version="1.0" encoding="UTF-8"?>
<!-- Generated by org.testng.reporters.JUnitReportReporter -->
<testsuite hostname="lenovo-PC" name="testNgPract.retryPrac" tests="6" failures="0" timestamp="28 Nov 2019 10:33:32 GMT" time="0.045" errors="5">
  <testcase name="t1" time="0.027" classname="testNgPract.retryPrac">
    <error type="java.lang.AssertionError" message="expected [true] but found [false]">
      <![CDATA[java.lang.AssertionError: expected [true] but found [false]
	at org.testng.Assert.fail(Assert.java:89)
	at org.testng.Assert.failNotEquals(Assert.java:489)
	at org.testng.Assert.assertEquals(Assert.java:118)
	at org.testng.Assert.assertEquals(Assert.java:281)
	at org.testng.Assert.assertEquals(Assert.java:291)
	at testNgPract.retryPrac.t1(retryPrac.java:11)
	at sun.reflect.NativeMethodAccessorImpl.invoke0(Native Method)
	at sun.reflect.NativeMethodAccessorImpl.invoke(Unknown Source)
	at sun.reflect.DelegatingMethodAccessorImpl.invoke(Unknown Source)
	at java.lang.reflect.Method.invoke(Unknown Source)
	at org.testng.internal.MethodInvocationHelper.invokeMethod(MethodInvocationHelper.java:80)
	at org.testng.internal.Invoker.invokeMethod(Invoker.java:715)
	at org.testng.internal.Invoker.invokeTestMethod(Invoker.java:907)
	at org.testng.internal.Invoker.invokeTestMethods(Invoker.java:1237)
	at org.testng.internal.TestMethodWorker.invokeTestMethods(TestMethodWorker.java:127)
	at org.testng.internal.TestMethodWorker.run(TestMethodWorker.java:111)
	at org.testng.TestRunner.privateRun(TestRunner.java:767)
	at org.testng.TestRunner.run(TestRunner.java:617)
	at org.testng.SuiteRunner.runTest(SuiteRunner.java:334)
	at org.testng.SuiteRunner.runSequentially(SuiteRunner.java:329)
	at org.testng.SuiteRunner.privateRun(SuiteRunner.java:291)
	at org.testng.SuiteRunner.run(SuiteRunner.java:240)
	at org.testng.SuiteRunnerWorker.runSuite(SuiteRunnerWorker.java:51)
	at org.testng.SuiteRunnerWorker.run(SuiteRunnerWorker.java:85)
	at org.testng.TestNG.runSuitesSequentially(TestNG.java:1197)
	at org.testng.TestNG.runSuitesLocally(TestNG.java:1122)
	at org.testng.TestNG.run(TestNG.java:1030)
	at org.testng.remote.AbstractRemoteTestNG.run(AbstractRemoteTestNG.java:132)
	at org.testng.remote.RemoteTestNG.initAndRun(RemoteTestNG.java:230)
	at org.testng.remote.RemoteTestNG.main(RemoteTestNG.java:76)
]]>
    </error>
  </testcase> <!-- t1 -->
  <testcase name="t3" time="0.003" classname="testNgPract.retryPrac"/>
  <testcase name="t2" time="0.003" classname="testNgPract.retryPrac">
    <error type="java.lang.AssertionError" message="expected [true] but found [false]">
      <![CDATA[java.lang.AssertionError: expected [true] but found [false]
	at org.testng.Assert.fail(Assert.java:89)
	at org.testng.Assert.failNotEquals(Assert.java:489)
	at org.testng.Assert.assertEquals(Assert.java:118)
	at org.testng.Assert.assertEquals(Assert.java:281)
	at org.testng.Assert.assertEquals(Assert.java:291)
	at testNgPract.retryPrac.t2(retryPrac.java:16)
	at sun.reflect.NativeMethodAccessorImpl.invoke0(Native Method)
	at sun.reflect.NativeMethodAccessorImpl.invoke(Unknown Source)
	at sun.reflect.DelegatingMethodAccessorImpl.invoke(Unknown Source)
	at java.lang.reflect.Method.invoke(Unknown Source)
	at org.testng.internal.MethodInvocationHelper.invokeMethod(MethodInvocationHelper.java:80)
	at org.testng.internal.Invoker.invokeMethod(Invoker.java:715)
	at org.testng.internal.Invoker.invokeTestMethod(Invoker.java:907)
	at org.testng.internal.Invoker.invokeTestMethods(Invoker.java:1237)
	at org.testng.internal.TestMethodWorker.invokeTestMethods(TestMethodWorker.java:127)
	at org.testng.internal.TestMethodWorker.run(TestMethodWorker.java:111)
	at org.testng.TestRunner.privateRun(TestRunner.java:767)
	at org.testng.TestRunner.run(TestRunner.java:617)
	at org.testng.SuiteRunner.runTest(SuiteRunner.java:334)
	at org.testng.SuiteRunner.runSequentially(SuiteRunner.java:329)
	at org.testng.SuiteRunner.privateRun(SuiteRunner.java:291)
	at org.testng.SuiteRunner.run(SuiteRunner.java:240)
	at org.testng.SuiteRunnerWorker.runSuite(SuiteRunnerWorker.java:51)
	at org.testng.SuiteRunnerWorker.run(SuiteRunnerWorker.java:85)
	at org.testng.TestNG.runSuitesSequentially(TestNG.java:1197)
	at org.testng.TestNG.runSuitesLocally(TestNG.java:1122)
	at org.testng.TestNG.run(TestNG.java:1030)
	at org.testng.remote.AbstractRemoteTestNG.run(AbstractRemoteTestNG.java:132)
	at org.testng.remote.RemoteTestNG.initAndRun(RemoteTestNG.java:230)
	at org.testng.remote.RemoteTestNG.main(RemoteTestNG.java:76)
]]>
    </error>
  </testcase> <!-- t2 -->
  <testcase name="t1" time="0.004" classname="testNgPract.retryPrac">
    <error type="java.lang.AssertionError" message="expected [true] but found [false]">
      <![CDATA[java.lang.AssertionError: expected [true] but found [false]
	at org.testng.Assert.fail(Assert.java:89)
	at org.testng.Assert.failNotEquals(Assert.java:489)
	at org.testng.Assert.assertEquals(Assert.java:118)
	at org.testng.Assert.assertEquals(Assert.java:281)
	at org.testng.Assert.assertEquals(Assert.java:291)
	at testNgPract.retryPrac.t1(retryPrac.java:11)
	at sun.reflect.NativeMethodAccessorImpl.invoke0(Native Method)
	at sun.reflect.NativeMethodAccessorImpl.invoke(Unknown Source)
	at sun.reflect.DelegatingMethodAccessorImpl.invoke(Unknown Source)
	at java.lang.reflect.Method.invoke(Unknown Source)
	at org.testng.internal.MethodInvocationHelper.invokeMethod(MethodInvocationHelper.java:80)
	at org.testng.internal.Invoker.invokeMethod(Invoker.java:715)
	at org.testng.internal.Invoker.retryFailed(Invoker.java:1055)
	at org.testng.internal.Invoker.invokeTestMethods(Invoker.java:1260)
	at org.testng.internal.TestMethodWorker.invokeTestMethods(TestMethodWorker.java:127)
	at org.testng.internal.TestMethodWorker.run(TestMethodWorker.java:111)
	at org.testng.TestRunner.privateRun(TestRunner.java:767)
	at org.testng.TestRunner.run(TestRunner.java:617)
	at org.testng.SuiteRunner.runTest(SuiteRunner.java:334)
	at org.testng.SuiteRunner.runSequentially(SuiteRunner.java:329)
	at org.testng.SuiteRunner.privateRun(SuiteRunner.java:291)
	at org.testng.SuiteRunner.run(SuiteRunner.java:240)
	at org.testng.SuiteRunnerWorker.runSuite(SuiteRunnerWorker.java:51)
	at org.testng.SuiteRunnerWorker.run(SuiteRunnerWorker.java:85)
	at org.testng.TestNG.runSuitesSequentially(TestNG.java:1197)
	at org.testng.TestNG.runSuitesLocally(TestNG.java:1122)
	at org.testng.TestNG.run(TestNG.java:1030)
	at org.testng.remote.AbstractRemoteTestNG.run(AbstractRemoteTestNG.java:132)
	at org.testng.remote.RemoteTestNG.initAndRun(RemoteTestNG.java:230)
	at org.testng.remote.RemoteTestNG.main(RemoteTestNG.java:76)
]]>
    </error>
  </testcase> <!-- t1 -->
  <testcase name="t1" time="0.005" classname="testNgPract.retryPrac">
    <error type="java.lang.AssertionError" message="expected [true] but found [false]">
      <![CDATA[java.lang.AssertionError: expected [true] but found [false]
	at org.testng.Assert.fail(Assert.java:89)
	at org.testng.Assert.failNotEquals(Assert.java:489)
	at org.testng.Assert.assertEquals(Assert.java:118)
	at org.testng.Assert.assertEquals(Assert.java:281)
	at org.testng.Assert.assertEquals(Assert.java:291)
	at testNgPract.retryPrac.t1(retryPrac.java:11)
	at sun.reflect.NativeMethodAccessorImpl.invoke0(Native Method)
	at sun.reflect.NativeMethodAccessorImpl.invoke(Unknown Source)
	at sun.reflect.DelegatingMethodAccessorImpl.invoke(Unknown Source)
	at java.lang.reflect.Method.invoke(Unknown Source)
	at org.testng.internal.MethodInvocationHelper.invokeMethod(MethodInvocationHelper.java:80)
	at org.testng.internal.Invoker.invokeMethod(Invoker.java:715)
	at org.testng.internal.Invoker.retryFailed(Invoker.java:1055)
	at org.testng.internal.Invoker.invokeTestMethods(Invoker.java:1260)
	at org.testng.internal.TestMethodWorker.invokeTestMethods(TestMethodWorker.java:127)
	at org.testng.internal.TestMethodWorker.run(TestMethodWorker.java:111)
	at org.testng.TestRunner.privateRun(TestRunner.java:767)
	at org.testng.TestRunner.run(TestRunner.java:617)
	at org.testng.SuiteRunner.runTest(SuiteRunner.java:334)
	at org.testng.SuiteRunner.runSequentially(SuiteRunner.java:329)
	at org.testng.SuiteRunner.privateRun(SuiteRunner.java:291)
	at org.testng.SuiteRunner.run(SuiteRunner.java:240)
	at org.testng.SuiteRunnerWorker.runSuite(SuiteRunnerWorker.java:51)
	at org.testng.SuiteRunnerWorker.run(SuiteRunnerWorker.java:85)
	at org.testng.TestNG.runSuitesSequentially(TestNG.java:1197)
	at org.testng.TestNG.runSuitesLocally(TestNG.java:1122)
	at org.testng.TestNG.run(TestNG.java:1030)
	at org.testng.remote.AbstractRemoteTestNG.run(AbstractRemoteTestNG.java:132)
	at org.testng.remote.RemoteTestNG.initAndRun(RemoteTestNG.java:230)
	at org.testng.remote.RemoteTestNG.main(RemoteTestNG.java:76)
]]>
    </error>
  </testcase> <!-- t1 -->
  <testcase name="t1" time="0.003" classname="testNgPract.retryPrac">
    <error type="java.lang.AssertionError" message="expected [true] but found [false]">
      <![CDATA[java.lang.AssertionError: expected [true] but found [false]
	at org.testng.Assert.fail(Assert.java:89)
	at org.testng.Assert.failNotEquals(Assert.java:489)
	at org.testng.Assert.assertEquals(Assert.java:118)
	at org.testng.Assert.assertEquals(Assert.java:281)
	at org.testng.Assert.assertEquals(Assert.java:291)
	at testNgPract.retryPrac.t1(retryPrac.java:11)
	at sun.reflect.NativeMethodAccessorImpl.invoke0(Native Method)
	at sun.reflect.NativeMethodAccessorImpl.invoke(Unknown Source)
	at sun.reflect.DelegatingMethodAccessorImpl.invoke(Unknown Source)
	at java.lang.reflect.Method.invoke(Unknown Source)
	at org.testng.internal.MethodInvocationHelper.invokeMethod(MethodInvocationHelper.java:80)
	at org.testng.internal.Invoker.invokeMethod(Invoker.java:715)
	at org.testng.internal.Invoker.retryFailed(Invoker.java:1055)
	at org.testng.internal.Invoker.invokeTestMethods(Invoker.java:1260)
	at org.testng.internal.TestMethodWorker.invokeTestMethods(TestMethodWorker.java:127)
	at org.testng.internal.TestMethodWorker.run(TestMethodWorker.java:111)
	at org.testng.TestRunner.privateRun(TestRunner.java:767)
	at org.testng.TestRunner.run(TestRunner.java:617)
	at org.testng.SuiteRunner.runTest(SuiteRunner.java:334)
	at org.testng.SuiteRunner.runSequentially(SuiteRunner.java:329)
	at org.testng.SuiteRunner.privateRun(SuiteRunner.java:291)
	at org.testng.SuiteRunner.run(SuiteRunner.java:240)
	at org.testng.SuiteRunnerWorker.runSuite(SuiteRunnerWorker.java:51)
	at org.testng.SuiteRunnerWorker.run(SuiteRunnerWorker.java:85)
	at org.testng.TestNG.runSuitesSequentially(TestNG.java:1197)
	at org.testng.TestNG.runSuitesLocally(TestNG.java:1122)
	at org.testng.TestNG.run(TestNG.java:1030)
	at org.testng.remote.AbstractRemoteTestNG.run(AbstractRemoteTestNG.java:132)
	at org.testng.remote.RemoteTestNG.initAndRun(RemoteTestNG.java:230)
	at org.testng.remote.RemoteTestNG.main(RemoteTestNG.java:76)
]]>
    </error>
  </testcase> <!-- t1 -->
</testsuite> <!-- testNgPract.retryPrac -->
